[nltk_data] Downloading package stopwords to /home/kc3585/nltk_data...
[nltk_data]   Package stopwords is already up-to-date!
[nltk_data] Downloading package punkt to /home/kc3585/nltk_data...
[nltk_data]   Package punkt is already up-to-date!
Traceback (most recent call last):
  File "/home/kc3585/NLP-Group-10-Final-Project/env/lib64/python3.6/site-packages/urllib3/connection.py", line 175, in _new_conn
    (self._dns_host, self.port), self.timeout, **extra_kw
  File "/home/kc3585/NLP-Group-10-Final-Project/env/lib64/python3.6/site-packages/urllib3/util/connection.py", line 96, in create_connection
    raise err
  File "/home/kc3585/NLP-Group-10-Final-Project/env/lib64/python3.6/site-packages/urllib3/util/connection.py", line 86, in create_connection
    sock.connect(sa)
OSError: [Errno 101] Network is unreachable

During handling of the above exception, another exception occurred:

Traceback (most recent call last):
  File "/home/kc3585/NLP-Group-10-Final-Project/env/lib64/python3.6/site-packages/urllib3/connectionpool.py", line 706, in urlopen
    chunked=chunked,
  File "/home/kc3585/NLP-Group-10-Final-Project/env/lib64/python3.6/site-packages/urllib3/connectionpool.py", line 382, in _make_request
    self._validate_conn(conn)
  File "/home/kc3585/NLP-Group-10-Final-Project/env/lib64/python3.6/site-packages/urllib3/connectionpool.py", line 1010, in _validate_conn
    conn.connect()
  File "/home/kc3585/NLP-Group-10-Final-Project/env/lib64/python3.6/site-packages/urllib3/connection.py", line 358, in connect
    conn = self._new_conn()
  File "/home/kc3585/NLP-Group-10-Final-Project/env/lib64/python3.6/site-packages/urllib3/connection.py", line 187, in _new_conn
    self, "Failed to establish a new connection: %s" % e
urllib3.exceptions.NewConnectionError: <urllib3.connection.HTTPSConnection object at 0x148ddee06ba8>: Failed to establish a new connection: [Errno 101] Network is unreachable

During handling of the above exception, another exception occurred:

Traceback (most recent call last):
  File "/home/kc3585/NLP-Group-10-Final-Project/env/lib64/python3.6/site-packages/requests/adapters.py", line 449, in send
    timeout=timeout
  File "/home/kc3585/NLP-Group-10-Final-Project/env/lib64/python3.6/site-packages/urllib3/connectionpool.py", line 756, in urlopen
    method, url, error=e, _pool=self, _stacktrace=sys.exc_info()[2]
  File "/home/kc3585/NLP-Group-10-Final-Project/env/lib64/python3.6/site-packages/urllib3/util/retry.py", line 574, in increment
    raise MaxRetryError(_pool, url, error or ResponseError(cause))
urllib3.exceptions.MaxRetryError: HTTPSConnectionPool(host='www.gutenberg.org', port=443): Max retries exceeded with url: /ebooks/419.txt.utf-8 (Caused by NewConnectionError('<urllib3.connection.HTTPSConnection object at 0x148ddee06ba8>: Failed to establish a new connection: [Errno 101] Network is unreachable',))

During handling of the above exception, another exception occurred:

Traceback (most recent call last):
  File "/home/kc3585/NLP-Group-10-Final-Project/lexile_library/bookparse.py", line 32, in parseBookText
    bookTextRequest = requests.get("https://www.gutenberg.org/ebooks/" + str(bookNum) + ".txt.utf-8")
  File "/home/kc3585/NLP-Group-10-Final-Project/env/lib64/python3.6/site-packages/requests/api.py", line 75, in get
    return request('get', url, params=params, **kwargs)
  File "/home/kc3585/NLP-Group-10-Final-Project/env/lib64/python3.6/site-packages/requests/api.py", line 61, in request
    return session.request(method=method, url=url, **kwargs)
  File "/home/kc3585/NLP-Group-10-Final-Project/env/lib64/python3.6/site-packages/requests/sessions.py", line 542, in request
    resp = self.send(prep, **send_kwargs)
  File "/home/kc3585/NLP-Group-10-Final-Project/env/lib64/python3.6/site-packages/requests/sessions.py", line 655, in send
    r = adapter.send(request, **kwargs)
  File "/home/kc3585/NLP-Group-10-Final-Project/env/lib64/python3.6/site-packages/requests/adapters.py", line 516, in send
    raise ConnectionError(e, request=request)
requests.exceptions.ConnectionError: HTTPSConnectionPool(host='www.gutenberg.org', port=443): Max retries exceeded with url: /ebooks/419.txt.utf-8 (Caused by NewConnectionError('<urllib3.connection.HTTPSConnection object at 0x148ddee06ba8>: Failed to establish a new connection: [Errno 101] Network is unreachable',))

During handling of the above exception, another exception occurred:

Traceback (most recent call last):
  File "/home/kc3585/NLP-Group-10-Final-Project/env/lib64/python3.6/site-packages/urllib3/connection.py", line 175, in _new_conn
    (self._dns_host, self.port), self.timeout, **extra_kw
  File "/home/kc3585/NLP-Group-10-Final-Project/env/lib64/python3.6/site-packages/urllib3/util/connection.py", line 96, in create_connection
    raise err
  File "/home/kc3585/NLP-Group-10-Final-Project/env/lib64/python3.6/site-packages/urllib3/util/connection.py", line 86, in create_connection
    sock.connect(sa)
OSError: [Errno 101] Network is unreachable

During handling of the above exception, another exception occurred:

Traceback (most recent call last):
  File "/home/kc3585/NLP-Group-10-Final-Project/env/lib64/python3.6/site-packages/urllib3/connectionpool.py", line 706, in urlopen
    chunked=chunked,
  File "/home/kc3585/NLP-Group-10-Final-Project/env/lib64/python3.6/site-packages/urllib3/connectionpool.py", line 382, in _make_request
    self._validate_conn(conn)
  File "/home/kc3585/NLP-Group-10-Final-Project/env/lib64/python3.6/site-packages/urllib3/connectionpool.py", line 1010, in _validate_conn
    conn.connect()
  File "/home/kc3585/NLP-Group-10-Final-Project/env/lib64/python3.6/site-packages/urllib3/connection.py", line 358, in connect
    conn = self._new_conn()
  File "/home/kc3585/NLP-Group-10-Final-Project/env/lib64/python3.6/site-packages/urllib3/connection.py", line 187, in _new_conn
    self, "Failed to establish a new connection: %s" % e
urllib3.exceptions.NewConnectionError: <urllib3.connection.HTTPSConnection object at 0x148ddedc1470>: Failed to establish a new connection: [Errno 101] Network is unreachable

During handling of the above exception, another exception occurred:

Traceback (most recent call last):
  File "/home/kc3585/NLP-Group-10-Final-Project/env/lib64/python3.6/site-packages/requests/adapters.py", line 449, in send
    timeout=timeout
  File "/home/kc3585/NLP-Group-10-Final-Project/env/lib64/python3.6/site-packages/urllib3/connectionpool.py", line 756, in urlopen
    method, url, error=e, _pool=self, _stacktrace=sys.exc_info()[2]
  File "/home/kc3585/NLP-Group-10-Final-Project/env/lib64/python3.6/site-packages/urllib3/util/retry.py", line 574, in increment
    raise MaxRetryError(_pool, url, error or ResponseError(cause))
urllib3.exceptions.MaxRetryError: HTTPSConnectionPool(host='www.gutenberg.org', port=443): Max retries exceeded with url: /files/419/419-0.txt (Caused by NewConnectionError('<urllib3.connection.HTTPSConnection object at 0x148ddedc1470>: Failed to establish a new connection: [Errno 101] Network is unreachable',))

During handling of the above exception, another exception occurred:

Traceback (most recent call last):
  File "main.py", line 18, in <module>
    bookMap = lx.parseBookText(bookTitles, bookNums)
  File "/home/kc3585/NLP-Group-10-Final-Project/lexile_library/bookparse.py", line 34, in parseBookText
    bookTextRequest = requests.get("https://www.gutenberg.org/files/" + str(bookNum) + "/" + str(bookNum) + "-0.txt")
  File "/home/kc3585/NLP-Group-10-Final-Project/env/lib64/python3.6/site-packages/requests/api.py", line 75, in get
    return request('get', url, params=params, **kwargs)
  File "/home/kc3585/NLP-Group-10-Final-Project/env/lib64/python3.6/site-packages/requests/api.py", line 61, in request
    return session.request(method=method, url=url, **kwargs)
  File "/home/kc3585/NLP-Group-10-Final-Project/env/lib64/python3.6/site-packages/requests/sessions.py", line 542, in request
    resp = self.send(prep, **send_kwargs)
  File "/home/kc3585/NLP-Group-10-Final-Project/env/lib64/python3.6/site-packages/requests/sessions.py", line 655, in send
    r = adapter.send(request, **kwargs)
  File "/home/kc3585/NLP-Group-10-Final-Project/env/lib64/python3.6/site-packages/requests/adapters.py", line 516, in send
    raise ConnectionError(e, request=request)
requests.exceptions.ConnectionError: HTTPSConnectionPool(host='www.gutenberg.org', port=443): Max retries exceeded with url: /files/419/419-0.txt (Caused by NewConnectionError('<urllib3.connection.HTTPSConnection object at 0x148ddedc1470>: Failed to establish a new connection: [Errno 101] Network is unreachable',))
